[2022-02-02 04:58:05,518] {taskinstance.py:1032} INFO - Dependencies all met for <TaskInstance: download_ingest_2_gcs_dag.local_to_gcs_job scheduled__2019-01-02T06:00:00+00:00 [queued]>
[2022-02-02 04:58:05,567] {taskinstance.py:1032} INFO - Dependencies all met for <TaskInstance: download_ingest_2_gcs_dag.local_to_gcs_job scheduled__2019-01-02T06:00:00+00:00 [queued]>
[2022-02-02 04:58:05,570] {taskinstance.py:1238} INFO - 
--------------------------------------------------------------------------------
[2022-02-02 04:58:05,571] {taskinstance.py:1239} INFO - Starting attempt 2 of 2
[2022-02-02 04:58:05,573] {taskinstance.py:1240} INFO - 
--------------------------------------------------------------------------------
[2022-02-02 04:58:05,621] {taskinstance.py:1259} INFO - Executing <Task(PythonOperator): local_to_gcs_job> on 2019-01-02 06:00:00+00:00
[2022-02-02 04:58:05,633] {standard_task_runner.py:52} INFO - Started process 4603 to run task
[2022-02-02 04:58:05,643] {standard_task_runner.py:76} INFO - Running: ['***', 'tasks', 'run', 'download_ingest_2_gcs_dag', 'local_to_gcs_job', 'scheduled__2019-01-02T06:00:00+00:00', '--job-id', '261', '--raw', '--subdir', 'DAGS_FOLDER/load_gsc_assgnment.py', '--cfg-path', '/tmp/tmpvh8o8yvp', '--error-file', '/tmp/tmpsea3qp4e']
[2022-02-02 04:58:05,647] {standard_task_runner.py:77} INFO - Job 261: Subtask local_to_gcs_job
[2022-02-02 04:58:05,782] {logging_mixin.py:109} INFO - Running <TaskInstance: download_ingest_2_gcs_dag.local_to_gcs_job scheduled__2019-01-02T06:00:00+00:00 [running]> on host 3082aca3aebc
[2022-02-02 04:58:05,922] {taskinstance.py:1426} INFO - Exporting the following env vars:
AIRFLOW_CTX_DAG_OWNER=***
AIRFLOW_CTX_DAG_ID=download_ingest_2_gcs_dag
AIRFLOW_CTX_TASK_ID=local_to_gcs_job
AIRFLOW_CTX_EXECUTION_DATE=2019-01-02T06:00:00+00:00
AIRFLOW_CTX_DAG_RUN_ID=scheduled__2019-01-02T06:00:00+00:00
[2022-02-02 04:58:06,019] {taskinstance.py:1700} ERROR - Task failed with exception
Traceback (most recent call last):
  File "/home/airflow/.local/lib/python3.7/site-packages/airflow/models/taskinstance.py", line 1329, in _run_raw_task
    self._execute_task_with_callbacks(context)
  File "/home/airflow/.local/lib/python3.7/site-packages/airflow/models/taskinstance.py", line 1455, in _execute_task_with_callbacks
    result = self._execute_task(context, self.task)
  File "/home/airflow/.local/lib/python3.7/site-packages/airflow/models/taskinstance.py", line 1511, in _execute_task
    result = execute_callable(context=context)
  File "/home/airflow/.local/lib/python3.7/site-packages/airflow/operators/python.py", line 174, in execute
    return_value = self.execute_callable()
  File "/home/airflow/.local/lib/python3.7/site-packages/airflow/operators/python.py", line 185, in execute_callable
    return self.python_callable(*self.op_args, **self.op_kwargs)
  File "/opt/airflow/dags/load_gsc_assgnment.py", line 53, in upload_to_gcs
    blob.upload_from_filename(local_file)
  File "/home/airflow/.local/lib/python3.7/site-packages/google/cloud/storage/blob.py", line 2720, in upload_from_filename
    with open(filename, "rb") as file_obj:
FileNotFoundError: [Errno 2] No such file or directory: '/opt/airflow/output_*.parquet'
[2022-02-02 04:58:06,063] {taskinstance.py:1277} INFO - Marking task as FAILED. dag_id=download_ingest_2_gcs_dag, task_id=local_to_gcs_job, execution_date=20190102T060000, start_date=20220202T045805, end_date=20220202T045806
[2022-02-02 04:58:06,107] {standard_task_runner.py:92} ERROR - Failed to execute job 261 for task local_to_gcs_job
Traceback (most recent call last):
  File "/home/airflow/.local/lib/python3.7/site-packages/airflow/task/task_runner/standard_task_runner.py", line 85, in _start_by_fork
    args.func(args, dag=self.dag)
  File "/home/airflow/.local/lib/python3.7/site-packages/airflow/cli/cli_parser.py", line 48, in command
    return func(*args, **kwargs)
  File "/home/airflow/.local/lib/python3.7/site-packages/airflow/utils/cli.py", line 92, in wrapper
    return f(*args, **kwargs)
  File "/home/airflow/.local/lib/python3.7/site-packages/airflow/cli/commands/task_command.py", line 298, in task_run
    _run_task_by_selected_method(args, dag, ti)
  File "/home/airflow/.local/lib/python3.7/site-packages/airflow/cli/commands/task_command.py", line 107, in _run_task_by_selected_method
    _run_raw_task(args, ti)
  File "/home/airflow/.local/lib/python3.7/site-packages/airflow/cli/commands/task_command.py", line 184, in _run_raw_task
    error_file=args.error_file,
  File "/home/airflow/.local/lib/python3.7/site-packages/airflow/utils/session.py", line 70, in wrapper
    return func(*args, session=session, **kwargs)
  File "/home/airflow/.local/lib/python3.7/site-packages/airflow/models/taskinstance.py", line 1329, in _run_raw_task
    self._execute_task_with_callbacks(context)
  File "/home/airflow/.local/lib/python3.7/site-packages/airflow/models/taskinstance.py", line 1455, in _execute_task_with_callbacks
    result = self._execute_task(context, self.task)
  File "/home/airflow/.local/lib/python3.7/site-packages/airflow/models/taskinstance.py", line 1511, in _execute_task
    result = execute_callable(context=context)
  File "/home/airflow/.local/lib/python3.7/site-packages/airflow/operators/python.py", line 174, in execute
    return_value = self.execute_callable()
  File "/home/airflow/.local/lib/python3.7/site-packages/airflow/operators/python.py", line 185, in execute_callable
    return self.python_callable(*self.op_args, **self.op_kwargs)
  File "/opt/airflow/dags/load_gsc_assgnment.py", line 53, in upload_to_gcs
    blob.upload_from_filename(local_file)
  File "/home/airflow/.local/lib/python3.7/site-packages/google/cloud/storage/blob.py", line 2720, in upload_from_filename
    with open(filename, "rb") as file_obj:
FileNotFoundError: [Errno 2] No such file or directory: '/opt/airflow/output_*.parquet'
[2022-02-02 04:58:06,144] {local_task_job.py:154} INFO - Task exited with return code 1
[2022-02-02 04:58:06,256] {local_task_job.py:264} INFO - 0 downstream tasks scheduled from follow-on schedule check
