[2022-02-02 05:34:16,356] {taskinstance.py:1032} INFO - Dependencies all met for <TaskInstance: download_ingest_2_gcs_dag.local_to_gcs_job scheduled__2019-01-02T06:00:00+00:00 [queued]>
[2022-02-02 05:34:16,408] {taskinstance.py:1032} INFO - Dependencies all met for <TaskInstance: download_ingest_2_gcs_dag.local_to_gcs_job scheduled__2019-01-02T06:00:00+00:00 [queued]>
[2022-02-02 05:34:16,410] {taskinstance.py:1238} INFO - 
--------------------------------------------------------------------------------
[2022-02-02 05:34:16,412] {taskinstance.py:1239} INFO - Starting attempt 8 of 8
[2022-02-02 05:34:16,415] {taskinstance.py:1240} INFO - 
--------------------------------------------------------------------------------
[2022-02-02 05:34:16,466] {taskinstance.py:1259} INFO - Executing <Task(PythonOperator): local_to_gcs_job> on 2019-01-02 06:00:00+00:00
[2022-02-02 05:34:16,482] {standard_task_runner.py:52} INFO - Started process 6566 to run task
[2022-02-02 05:34:16,501] {standard_task_runner.py:76} INFO - Running: ['***', 'tasks', 'run', 'download_ingest_2_gcs_dag', 'local_to_gcs_job', 'scheduled__2019-01-02T06:00:00+00:00', '--job-id', '269', '--raw', '--subdir', 'DAGS_FOLDER/load_gsc_assgnment.py', '--cfg-path', '/tmp/tmpsv86k0e7', '--error-file', '/tmp/tmpt2tmdvm8']
[2022-02-02 05:34:16,505] {standard_task_runner.py:77} INFO - Job 269: Subtask local_to_gcs_job
[2022-02-02 05:34:16,707] {logging_mixin.py:109} INFO - Running <TaskInstance: download_ingest_2_gcs_dag.local_to_gcs_job scheduled__2019-01-02T06:00:00+00:00 [running]> on host 3082aca3aebc
[2022-02-02 05:34:16,867] {warnings.py:110} WARNING - /home/***/.local/lib/python3.7/site-packages/***/utils/context.py:152: AirflowContextDeprecationWarning: Accessing 'execution_date' from the template is deprecated and will be removed in a future version. Please use 'data_interval_start' or 'logical_date' instead.
  warnings.warn(_create_deprecation_warning(key, self._deprecation_replacements[key]))

[2022-02-02 05:34:16,933] {taskinstance.py:1426} INFO - Exporting the following env vars:
AIRFLOW_CTX_DAG_OWNER=***
AIRFLOW_CTX_DAG_ID=download_ingest_2_gcs_dag
AIRFLOW_CTX_TASK_ID=local_to_gcs_job
AIRFLOW_CTX_EXECUTION_DATE=2019-01-02T06:00:00+00:00
AIRFLOW_CTX_DAG_RUN_ID=scheduled__2019-01-02T06:00:00+00:00
[2022-02-02 05:34:42,137] {local_task_job.py:212} WARNING - State of this instance has been externally set to restarting. Terminating instance.
[2022-02-02 05:34:42,150] {process_utils.py:124} INFO - Sending Signals.SIGTERM to group 6566. PIDs of all processes in the group: [6566]
[2022-02-02 05:34:42,153] {process_utils.py:75} INFO - Sending the signal Signals.SIGTERM to group 6566
[2022-02-02 05:34:42,158] {taskinstance.py:1408} ERROR - Received SIGTERM. Terminating subprocesses.
[2022-02-02 05:34:42,214] {taskinstance.py:1700} ERROR - Task failed with exception
Traceback (most recent call last):
  File "/home/airflow/.local/lib/python3.7/site-packages/airflow/models/taskinstance.py", line 1329, in _run_raw_task
    self._execute_task_with_callbacks(context)
  File "/home/airflow/.local/lib/python3.7/site-packages/airflow/models/taskinstance.py", line 1455, in _execute_task_with_callbacks
    result = self._execute_task(context, self.task)
  File "/home/airflow/.local/lib/python3.7/site-packages/airflow/models/taskinstance.py", line 1511, in _execute_task
    result = execute_callable(context=context)
  File "/home/airflow/.local/lib/python3.7/site-packages/airflow/operators/python.py", line 174, in execute
    return_value = self.execute_callable()
  File "/home/airflow/.local/lib/python3.7/site-packages/airflow/operators/python.py", line 185, in execute_callable
    return self.python_callable(*self.op_args, **self.op_kwargs)
  File "/opt/airflow/dags/load_gsc_assgnment.py", line 53, in upload_to_gcs
    blob.upload_from_filename(local_file)
  File "/home/airflow/.local/lib/python3.7/site-packages/google/cloud/storage/blob.py", line 2735, in upload_from_filename
    retry=retry,
  File "/home/airflow/.local/lib/python3.7/site-packages/google/cloud/storage/blob.py", line 2594, in upload_from_file
    retry=retry,
  File "/home/airflow/.local/lib/python3.7/site-packages/google/cloud/storage/blob.py", line 2412, in _do_upload
    retry=retry,
  File "/home/airflow/.local/lib/python3.7/site-packages/google/cloud/storage/blob.py", line 2242, in _do_resumable_upload
    response = upload.transmit_next_chunk(transport, timeout=timeout)
  File "/home/airflow/.local/lib/python3.7/site-packages/google/resumable_media/requests/upload.py", line 516, in transmit_next_chunk
    retriable_request, self._get_status_code, self._retry_strategy
  File "/home/airflow/.local/lib/python3.7/site-packages/google/resumable_media/requests/_request_helpers.py", line 147, in wait_and_retry
    response = func()
  File "/home/airflow/.local/lib/python3.7/site-packages/google/resumable_media/requests/upload.py", line 508, in retriable_request
    method, url, data=payload, headers=headers, timeout=timeout
  File "/home/airflow/.local/lib/python3.7/site-packages/google/auth/transport/requests.py", line 486, in request
    **kwargs
  File "/home/airflow/.local/lib/python3.7/site-packages/requests/sessions.py", line 542, in request
    resp = self.send(prep, **send_kwargs)
  File "/home/airflow/.local/lib/python3.7/site-packages/requests/sessions.py", line 655, in send
    r = adapter.send(request, **kwargs)
  File "/home/airflow/.local/lib/python3.7/site-packages/requests/adapters.py", line 449, in send
    timeout=timeout
  File "/home/airflow/.local/lib/python3.7/site-packages/urllib3/connectionpool.py", line 706, in urlopen
    chunked=chunked,
  File "/home/airflow/.local/lib/python3.7/site-packages/urllib3/connectionpool.py", line 445, in _make_request
    six.raise_from(e, None)
  File "<string>", line 3, in raise_from
  File "/home/airflow/.local/lib/python3.7/site-packages/urllib3/connectionpool.py", line 440, in _make_request
    httplib_response = conn.getresponse()
  File "/usr/local/lib/python3.7/http/client.py", line 1373, in getresponse
    response.begin()
  File "/usr/local/lib/python3.7/http/client.py", line 319, in begin
    version, status, reason = self._read_status()
  File "/usr/local/lib/python3.7/http/client.py", line 280, in _read_status
    line = str(self.fp.readline(_MAXLINE + 1), "iso-8859-1")
  File "/usr/local/lib/python3.7/socket.py", line 589, in readinto
    return self._sock.recv_into(b)
  File "/usr/local/lib/python3.7/ssl.py", line 1071, in recv_into
    return self.read(nbytes, buffer)
  File "/usr/local/lib/python3.7/ssl.py", line 929, in read
    return self._sslobj.read(len, buffer)
  File "/home/airflow/.local/lib/python3.7/site-packages/airflow/models/taskinstance.py", line 1410, in signal_handler
    raise AirflowException("Task received SIGTERM signal")
airflow.exceptions.AirflowException: Task received SIGTERM signal
[2022-02-02 05:34:42,289] {taskinstance.py:1277} INFO - Marking task as UP_FOR_RETRY. dag_id=download_ingest_2_gcs_dag, task_id=local_to_gcs_job, execution_date=20190102T060000, start_date=20220202T053416, end_date=20220202T053442
[2022-02-02 05:34:42,357] {standard_task_runner.py:92} ERROR - Failed to execute job 269 for task local_to_gcs_job
Traceback (most recent call last):
  File "/home/airflow/.local/lib/python3.7/site-packages/airflow/task/task_runner/standard_task_runner.py", line 85, in _start_by_fork
    args.func(args, dag=self.dag)
  File "/home/airflow/.local/lib/python3.7/site-packages/airflow/cli/cli_parser.py", line 48, in command
    return func(*args, **kwargs)
  File "/home/airflow/.local/lib/python3.7/site-packages/airflow/utils/cli.py", line 92, in wrapper
    return f(*args, **kwargs)
  File "/home/airflow/.local/lib/python3.7/site-packages/airflow/cli/commands/task_command.py", line 298, in task_run
    _run_task_by_selected_method(args, dag, ti)
  File "/home/airflow/.local/lib/python3.7/site-packages/airflow/cli/commands/task_command.py", line 107, in _run_task_by_selected_method
    _run_raw_task(args, ti)
  File "/home/airflow/.local/lib/python3.7/site-packages/airflow/cli/commands/task_command.py", line 184, in _run_raw_task
    error_file=args.error_file,
  File "/home/airflow/.local/lib/python3.7/site-packages/airflow/utils/session.py", line 70, in wrapper
    return func(*args, session=session, **kwargs)
  File "/home/airflow/.local/lib/python3.7/site-packages/airflow/models/taskinstance.py", line 1329, in _run_raw_task
    self._execute_task_with_callbacks(context)
  File "/home/airflow/.local/lib/python3.7/site-packages/airflow/models/taskinstance.py", line 1455, in _execute_task_with_callbacks
    result = self._execute_task(context, self.task)
  File "/home/airflow/.local/lib/python3.7/site-packages/airflow/models/taskinstance.py", line 1511, in _execute_task
    result = execute_callable(context=context)
  File "/home/airflow/.local/lib/python3.7/site-packages/airflow/operators/python.py", line 174, in execute
    return_value = self.execute_callable()
  File "/home/airflow/.local/lib/python3.7/site-packages/airflow/operators/python.py", line 185, in execute_callable
    return self.python_callable(*self.op_args, **self.op_kwargs)
  File "/opt/airflow/dags/load_gsc_assgnment.py", line 53, in upload_to_gcs
    blob.upload_from_filename(local_file)
  File "/home/airflow/.local/lib/python3.7/site-packages/google/cloud/storage/blob.py", line 2735, in upload_from_filename
    retry=retry,
  File "/home/airflow/.local/lib/python3.7/site-packages/google/cloud/storage/blob.py", line 2594, in upload_from_file
    retry=retry,
  File "/home/airflow/.local/lib/python3.7/site-packages/google/cloud/storage/blob.py", line 2412, in _do_upload
    retry=retry,
  File "/home/airflow/.local/lib/python3.7/site-packages/google/cloud/storage/blob.py", line 2242, in _do_resumable_upload
    response = upload.transmit_next_chunk(transport, timeout=timeout)
  File "/home/airflow/.local/lib/python3.7/site-packages/google/resumable_media/requests/upload.py", line 516, in transmit_next_chunk
    retriable_request, self._get_status_code, self._retry_strategy
  File "/home/airflow/.local/lib/python3.7/site-packages/google/resumable_media/requests/_request_helpers.py", line 147, in wait_and_retry
    response = func()
  File "/home/airflow/.local/lib/python3.7/site-packages/google/resumable_media/requests/upload.py", line 508, in retriable_request
    method, url, data=payload, headers=headers, timeout=timeout
  File "/home/airflow/.local/lib/python3.7/site-packages/google/auth/transport/requests.py", line 486, in request
    **kwargs
  File "/home/airflow/.local/lib/python3.7/site-packages/requests/sessions.py", line 542, in request
    resp = self.send(prep, **send_kwargs)
  File "/home/airflow/.local/lib/python3.7/site-packages/requests/sessions.py", line 655, in send
    r = adapter.send(request, **kwargs)
  File "/home/airflow/.local/lib/python3.7/site-packages/requests/adapters.py", line 449, in send
    timeout=timeout
  File "/home/airflow/.local/lib/python3.7/site-packages/urllib3/connectionpool.py", line 706, in urlopen
    chunked=chunked,
  File "/home/airflow/.local/lib/python3.7/site-packages/urllib3/connectionpool.py", line 445, in _make_request
    six.raise_from(e, None)
  File "<string>", line 3, in raise_from
  File "/home/airflow/.local/lib/python3.7/site-packages/urllib3/connectionpool.py", line 440, in _make_request
    httplib_response = conn.getresponse()
  File "/usr/local/lib/python3.7/http/client.py", line 1373, in getresponse
    response.begin()
  File "/usr/local/lib/python3.7/http/client.py", line 319, in begin
    version, status, reason = self._read_status()
  File "/usr/local/lib/python3.7/http/client.py", line 280, in _read_status
    line = str(self.fp.readline(_MAXLINE + 1), "iso-8859-1")
  File "/usr/local/lib/python3.7/socket.py", line 589, in readinto
    return self._sock.recv_into(b)
  File "/usr/local/lib/python3.7/ssl.py", line 1071, in recv_into
    return self.read(nbytes, buffer)
  File "/usr/local/lib/python3.7/ssl.py", line 929, in read
    return self._sslobj.read(len, buffer)
  File "/home/airflow/.local/lib/python3.7/site-packages/airflow/models/taskinstance.py", line 1410, in signal_handler
    raise AirflowException("Task received SIGTERM signal")
airflow.exceptions.AirflowException: Task received SIGTERM signal
[2022-02-02 05:34:42,421] {process_utils.py:70} INFO - Process psutil.Process(pid=6566, status='terminated', exitcode=1, started='05:34:16') (6566) terminated with exit code 1
