[2022-02-02 23:19:44,097] {taskinstance.py:1032} INFO - Dependencies all met for <TaskInstance: zone_ingest_2_gcs_dag.cleanup_csv_zone manual__2022-02-02T23:19:10.194243+00:00 [queued]>
[2022-02-02 23:19:44,150] {taskinstance.py:1032} INFO - Dependencies all met for <TaskInstance: zone_ingest_2_gcs_dag.cleanup_csv_zone manual__2022-02-02T23:19:10.194243+00:00 [queued]>
[2022-02-02 23:19:44,152] {taskinstance.py:1238} INFO - 
--------------------------------------------------------------------------------
[2022-02-02 23:19:44,154] {taskinstance.py:1239} INFO - Starting attempt 1 of 1
[2022-02-02 23:19:44,155] {taskinstance.py:1240} INFO - 
--------------------------------------------------------------------------------
[2022-02-02 23:19:44,214] {taskinstance.py:1259} INFO - Executing <Task(BashOperator): cleanup_csv_zone> on 2022-02-02 23:19:10.194243+00:00
[2022-02-02 23:19:44,229] {standard_task_runner.py:52} INFO - Started process 7098 to run task
[2022-02-02 23:19:44,239] {standard_task_runner.py:76} INFO - Running: ['***', 'tasks', 'run', 'zone_ingest_2_gcs_dag', 'cleanup_csv_zone', 'manual__2022-02-02T23:19:10.194243+00:00', '--job-id', '519', '--raw', '--subdir', 'DAGS_FOLDER/zone_download_ingest_gcs.py', '--cfg-path', '/tmp/tmp4_lek1tc', '--error-file', '/tmp/tmp9po0tewg']
[2022-02-02 23:19:44,243] {standard_task_runner.py:77} INFO - Job 519: Subtask cleanup_csv_zone
[2022-02-02 23:19:44,397] {logging_mixin.py:109} INFO - Running <TaskInstance: zone_ingest_2_gcs_dag.cleanup_csv_zone manual__2022-02-02T23:19:10.194243+00:00 [running]> on host ee5c3eebd1b1
[2022-02-02 23:19:44,581] {taskinstance.py:1426} INFO - Exporting the following env vars:
AIRFLOW_CTX_DAG_OWNER=***
AIRFLOW_CTX_DAG_ID=zone_ingest_2_gcs_dag
AIRFLOW_CTX_TASK_ID=cleanup_csv_zone
AIRFLOW_CTX_EXECUTION_DATE=2022-02-02T23:19:10.194243+00:00
AIRFLOW_CTX_DAG_RUN_ID=manual__2022-02-02T23:19:10.194243+00:00
[2022-02-02 23:19:44,590] {subprocess.py:62} INFO - Tmp dir root location: 
 /tmp
[2022-02-02 23:19:44,595] {subprocess.py:74} INFO - Running command: ['bash', '-c', 'rm /opt/***/taxi+_zone_lookup.csv']
[2022-02-02 23:19:44,624] {subprocess.py:85} INFO - Output:
[2022-02-02 23:19:44,728] {subprocess.py:89} INFO - /bin/rm: cannot remove '/opt/***/taxi+_zone_lookup.csv': No such file or directory
[2022-02-02 23:19:44,731] {subprocess.py:93} INFO - Command exited with return code 1
[2022-02-02 23:19:44,796] {taskinstance.py:1700} ERROR - Task failed with exception
Traceback (most recent call last):
  File "/home/airflow/.local/lib/python3.7/site-packages/airflow/models/taskinstance.py", line 1329, in _run_raw_task
    self._execute_task_with_callbacks(context)
  File "/home/airflow/.local/lib/python3.7/site-packages/airflow/models/taskinstance.py", line 1455, in _execute_task_with_callbacks
    result = self._execute_task(context, self.task)
  File "/home/airflow/.local/lib/python3.7/site-packages/airflow/models/taskinstance.py", line 1511, in _execute_task
    result = execute_callable(context=context)
  File "/home/airflow/.local/lib/python3.7/site-packages/airflow/operators/bash.py", line 188, in execute
    f'Bash command failed. The command returned a non-zero exit code {result.exit_code}.'
airflow.exceptions.AirflowException: Bash command failed. The command returned a non-zero exit code 1.
[2022-02-02 23:19:44,840] {taskinstance.py:1277} INFO - Marking task as FAILED. dag_id=zone_ingest_2_gcs_dag, task_id=cleanup_csv_zone, execution_date=20220202T231910, start_date=20220202T231944, end_date=20220202T231944
[2022-02-02 23:19:44,947] {standard_task_runner.py:92} ERROR - Failed to execute job 519 for task cleanup_csv_zone
Traceback (most recent call last):
  File "/home/airflow/.local/lib/python3.7/site-packages/airflow/task/task_runner/standard_task_runner.py", line 85, in _start_by_fork
    args.func(args, dag=self.dag)
  File "/home/airflow/.local/lib/python3.7/site-packages/airflow/cli/cli_parser.py", line 48, in command
    return func(*args, **kwargs)
  File "/home/airflow/.local/lib/python3.7/site-packages/airflow/utils/cli.py", line 92, in wrapper
    return f(*args, **kwargs)
  File "/home/airflow/.local/lib/python3.7/site-packages/airflow/cli/commands/task_command.py", line 298, in task_run
    _run_task_by_selected_method(args, dag, ti)
  File "/home/airflow/.local/lib/python3.7/site-packages/airflow/cli/commands/task_command.py", line 107, in _run_task_by_selected_method
    _run_raw_task(args, ti)
  File "/home/airflow/.local/lib/python3.7/site-packages/airflow/cli/commands/task_command.py", line 184, in _run_raw_task
    error_file=args.error_file,
  File "/home/airflow/.local/lib/python3.7/site-packages/airflow/utils/session.py", line 70, in wrapper
    return func(*args, session=session, **kwargs)
  File "/home/airflow/.local/lib/python3.7/site-packages/airflow/models/taskinstance.py", line 1329, in _run_raw_task
    self._execute_task_with_callbacks(context)
  File "/home/airflow/.local/lib/python3.7/site-packages/airflow/models/taskinstance.py", line 1455, in _execute_task_with_callbacks
    result = self._execute_task(context, self.task)
  File "/home/airflow/.local/lib/python3.7/site-packages/airflow/models/taskinstance.py", line 1511, in _execute_task
    result = execute_callable(context=context)
  File "/home/airflow/.local/lib/python3.7/site-packages/airflow/operators/bash.py", line 188, in execute
    f'Bash command failed. The command returned a non-zero exit code {result.exit_code}.'
airflow.exceptions.AirflowException: Bash command failed. The command returned a non-zero exit code 1.
[2022-02-02 23:19:45,015] {local_task_job.py:154} INFO - Task exited with return code 1
[2022-02-02 23:19:45,198] {local_task_job.py:264} INFO - 0 downstream tasks scheduled from follow-on schedule check
