[2022-02-15 21:15:59,639] {taskinstance.py:1032} INFO - Dependencies all met for <TaskInstance: yellow_taxi_download_csv.csv_to_gcs_job scheduled__2019-02-02T06:00:00+00:00 [queued]>
[2022-02-15 21:15:59,821] {taskinstance.py:1032} INFO - Dependencies all met for <TaskInstance: yellow_taxi_download_csv.csv_to_gcs_job scheduled__2019-02-02T06:00:00+00:00 [queued]>
[2022-02-15 21:15:59,830] {taskinstance.py:1238} INFO - 
--------------------------------------------------------------------------------
[2022-02-15 21:15:59,832] {taskinstance.py:1239} INFO - Starting attempt 1 of 1
[2022-02-15 21:15:59,834] {taskinstance.py:1240} INFO - 
--------------------------------------------------------------------------------
[2022-02-15 21:16:00,015] {taskinstance.py:1259} INFO - Executing <Task(PythonOperator): csv_to_gcs_job> on 2019-02-02 06:00:00+00:00
[2022-02-15 21:16:00,046] {standard_task_runner.py:52} INFO - Started process 473 to run task
[2022-02-15 21:16:00,083] {standard_task_runner.py:76} INFO - Running: ['***', 'tasks', 'run', 'yellow_taxi_download_csv', 'csv_to_gcs_job', 'scheduled__2019-02-02T06:00:00+00:00', '--job-id', '688', '--raw', '--subdir', 'DAGS_FOLDER/download_upload_yellowtaxi_csv.py', '--cfg-path', '/tmp/tmpot_mzprz', '--error-file', '/tmp/tmpix6gjqrz']
[2022-02-15 21:16:00,094] {standard_task_runner.py:77} INFO - Job 688: Subtask csv_to_gcs_job
[2022-02-15 21:16:00,547] {logging_mixin.py:109} INFO - Running <TaskInstance: yellow_taxi_download_csv.csv_to_gcs_job scheduled__2019-02-02T06:00:00+00:00 [running]> on host 29988b24dbed
[2022-02-15 21:16:01,022] {taskinstance.py:1426} INFO - Exporting the following env vars:
AIRFLOW_CTX_DAG_OWNER=***
AIRFLOW_CTX_DAG_ID=yellow_taxi_download_csv
AIRFLOW_CTX_TASK_ID=csv_to_gcs_job
AIRFLOW_CTX_EXECUTION_DATE=2019-02-02T06:00:00+00:00
AIRFLOW_CTX_DAG_RUN_ID=scheduled__2019-02-02T06:00:00+00:00
[2022-02-15 21:16:01,426] {taskinstance.py:1700} ERROR - Task failed with exception
Traceback (most recent call last):
  File "/home/airflow/.local/lib/python3.7/site-packages/airflow/models/taskinstance.py", line 1329, in _run_raw_task
    self._execute_task_with_callbacks(context)
  File "/home/airflow/.local/lib/python3.7/site-packages/airflow/models/taskinstance.py", line 1455, in _execute_task_with_callbacks
    result = self._execute_task(context, self.task)
  File "/home/airflow/.local/lib/python3.7/site-packages/airflow/models/taskinstance.py", line 1511, in _execute_task
    result = execute_callable(context=context)
  File "/home/airflow/.local/lib/python3.7/site-packages/airflow/operators/python.py", line 174, in execute
    return_value = self.execute_callable()
  File "/home/airflow/.local/lib/python3.7/site-packages/airflow/operators/python.py", line 185, in execute_callable
    return self.python_callable(*self.op_args, **self.op_kwargs)
  File "/opt/airflow/dags/download_upload_yellowtaxi_csv.py", line 37, in upload_to_gcs
    blob.upload_from_filename(local_file)
  File "/home/airflow/.local/lib/python3.7/site-packages/google/cloud/storage/blob.py", line 2720, in upload_from_filename
    with open(filename, "rb") as file_obj:
FileNotFoundError: [Errno 2] No such file or directory: '/opt/airflow//opt/airflow/output_*.csv'
[2022-02-15 21:16:01,600] {taskinstance.py:1277} INFO - Marking task as FAILED. dag_id=yellow_taxi_download_csv, task_id=csv_to_gcs_job, execution_date=20190202T060000, start_date=20220215T211559, end_date=20220215T211601
[2022-02-15 21:16:01,901] {standard_task_runner.py:92} ERROR - Failed to execute job 688 for task csv_to_gcs_job
Traceback (most recent call last):
  File "/home/airflow/.local/lib/python3.7/site-packages/airflow/task/task_runner/standard_task_runner.py", line 85, in _start_by_fork
    args.func(args, dag=self.dag)
  File "/home/airflow/.local/lib/python3.7/site-packages/airflow/cli/cli_parser.py", line 48, in command
    return func(*args, **kwargs)
  File "/home/airflow/.local/lib/python3.7/site-packages/airflow/utils/cli.py", line 92, in wrapper
    return f(*args, **kwargs)
  File "/home/airflow/.local/lib/python3.7/site-packages/airflow/cli/commands/task_command.py", line 298, in task_run
    _run_task_by_selected_method(args, dag, ti)
  File "/home/airflow/.local/lib/python3.7/site-packages/airflow/cli/commands/task_command.py", line 107, in _run_task_by_selected_method
    _run_raw_task(args, ti)
  File "/home/airflow/.local/lib/python3.7/site-packages/airflow/cli/commands/task_command.py", line 184, in _run_raw_task
    error_file=args.error_file,
  File "/home/airflow/.local/lib/python3.7/site-packages/airflow/utils/session.py", line 70, in wrapper
    return func(*args, session=session, **kwargs)
  File "/home/airflow/.local/lib/python3.7/site-packages/airflow/models/taskinstance.py", line 1329, in _run_raw_task
    self._execute_task_with_callbacks(context)
  File "/home/airflow/.local/lib/python3.7/site-packages/airflow/models/taskinstance.py", line 1455, in _execute_task_with_callbacks
    result = self._execute_task(context, self.task)
  File "/home/airflow/.local/lib/python3.7/site-packages/airflow/models/taskinstance.py", line 1511, in _execute_task
    result = execute_callable(context=context)
  File "/home/airflow/.local/lib/python3.7/site-packages/airflow/operators/python.py", line 174, in execute
    return_value = self.execute_callable()
  File "/home/airflow/.local/lib/python3.7/site-packages/airflow/operators/python.py", line 185, in execute_callable
    return self.python_callable(*self.op_args, **self.op_kwargs)
  File "/opt/airflow/dags/download_upload_yellowtaxi_csv.py", line 37, in upload_to_gcs
    blob.upload_from_filename(local_file)
  File "/home/airflow/.local/lib/python3.7/site-packages/google/cloud/storage/blob.py", line 2720, in upload_from_filename
    with open(filename, "rb") as file_obj:
FileNotFoundError: [Errno 2] No such file or directory: '/opt/airflow//opt/airflow/output_*.csv'
[2022-02-15 21:16:02,034] {local_task_job.py:154} INFO - Task exited with return code 1
[2022-02-15 21:16:02,450] {local_task_job.py:264} INFO - 0 downstream tasks scheduled from follow-on schedule check
