[2022-01-27 14:45:22,213] {taskinstance.py:1032} INFO - Dependencies all met for <TaskInstance: data_ingestion_gcs_dag.gcs_to_bq_task manual__2022-01-27T14:45:16.671236+00:00 [queued]>
[2022-01-27 14:45:22,276] {taskinstance.py:1032} INFO - Dependencies all met for <TaskInstance: data_ingestion_gcs_dag.gcs_to_bq_task manual__2022-01-27T14:45:16.671236+00:00 [queued]>
[2022-01-27 14:45:22,278] {taskinstance.py:1238} INFO - 
--------------------------------------------------------------------------------
[2022-01-27 14:45:22,283] {taskinstance.py:1239} INFO - Starting attempt 1 of 2
[2022-01-27 14:45:22,285] {taskinstance.py:1240} INFO - 
--------------------------------------------------------------------------------
[2022-01-27 14:45:22,362] {taskinstance.py:1259} INFO - Executing <Task(GCSToBigQueryOperator): gcs_to_bq_task> on 2022-01-27 14:45:16.671236+00:00
[2022-01-27 14:45:22,377] {standard_task_runner.py:52} INFO - Started process 2493 to run task
[2022-01-27 14:45:22,401] {standard_task_runner.py:76} INFO - Running: ['***', 'tasks', 'run', 'data_ingestion_gcs_dag', 'gcs_to_bq_task', 'manual__2022-01-27T14:45:16.671236+00:00', '--job-id', '10', '--raw', '--subdir', 'DAGS_FOLDER/data_ingestion_gcs_dag.py', '--cfg-path', '/tmp/tmp3yxen2da', '--error-file', '/tmp/tmpg95xhpnx']
[2022-01-27 14:45:22,405] {standard_task_runner.py:77} INFO - Job 10: Subtask gcs_to_bq_task
[2022-01-27 14:45:22,611] {logging_mixin.py:109} INFO - Running <TaskInstance: data_ingestion_gcs_dag.gcs_to_bq_task manual__2022-01-27T14:45:16.671236+00:00 [running]> on host 7b36948ad079
[2022-01-27 14:45:22,848] {taskinstance.py:1426} INFO - Exporting the following env vars:
AIRFLOW_CTX_DAG_OWNER=***
AIRFLOW_CTX_DAG_ID=data_ingestion_gcs_dag
AIRFLOW_CTX_TASK_ID=gcs_to_bq_task
AIRFLOW_CTX_EXECUTION_DATE=2022-01-27T14:45:16.671236+00:00
AIRFLOW_CTX_DAG_RUN_ID=manual__2022-01-27T14:45:16.671236+00:00
[2022-01-27 14:45:22,857] {warnings.py:110} WARNING - /home/***/.local/lib/python3.7/site-packages/***/providers/google/cloud/transfers/gcs_to_bigquery.py:261: DeprecationWarning: The bigquery_conn_id parameter has been deprecated. You should pass the gcp_conn_id parameter.
  impersonation_chain=self.impersonation_chain,

[2022-01-27 14:45:22,864] {crypto.py:82} WARNING - empty cryptography key - values will not be stored encrypted.
[2022-01-27 14:45:22,873] {warnings.py:110} WARNING - /home/***/.local/lib/python3.7/site-packages/***/providers/google/cloud/hooks/bigquery.py:141: DeprecationWarning: This method will be deprecated. Please use `BigQueryHook.get_client` method
  "This method will be deprecated. Please use `BigQueryHook.get_client` method", DeprecationWarning

[2022-01-27 14:45:23,706] {warnings.py:110} WARNING - /home/***/.local/lib/python3.7/site-packages/***/models/taskinstance.py:1511: DeprecationWarning: This method is deprecated. Please use `***.providers.google.cloud.hooks.bigquery.BigQueryHook.run_load`
  result = execute_callable(context=context)

[2022-01-27 14:45:23,709] {warnings.py:110} WARNING - /home/***/.local/lib/python3.7/site-packages/***/providers/google/cloud/hooks/bigquery.py:1772: DeprecationWarning: This method is deprecated. Please use `BigQueryHook.insert_job` method.
  "This method is deprecated. Please use `BigQueryHook.insert_job` method.", DeprecationWarning

[2022-01-27 14:45:23,712] {bigquery.py:3001} INFO - Project not included in destination_project_dataset_table: ny_trips_from_dag.trips_data_all; using project "dataengineering-bizzy"
[2022-01-27 14:45:23,716] {bigquery.py:1637} INFO - Inserting job ***_1643294723714822_914cdf4738e399597dd485687df4b252
[2022-01-27 14:45:24,161] {taskinstance.py:1700} ERROR - Task failed with exception
Traceback (most recent call last):
  File "/home/airflow/.local/lib/python3.7/site-packages/airflow/models/taskinstance.py", line 1329, in _run_raw_task
    self._execute_task_with_callbacks(context)
  File "/home/airflow/.local/lib/python3.7/site-packages/airflow/models/taskinstance.py", line 1455, in _execute_task_with_callbacks
    result = self._execute_task(context, self.task)
  File "/home/airflow/.local/lib/python3.7/site-packages/airflow/models/taskinstance.py", line 1511, in _execute_task
    result = execute_callable(context=context)
  File "/home/airflow/.local/lib/python3.7/site-packages/airflow/providers/google/cloud/transfers/gcs_to_bigquery.py", line 329, in execute
    description=self.description,
  File "/home/airflow/.local/lib/python3.7/site-packages/airflow/providers/google/cloud/hooks/bigquery.py", line 2682, in run_load
    return self.hook.run_load(*args, **kwargs)
  File "/home/airflow/.local/lib/python3.7/site-packages/airflow/providers/google/cloud/hooks/bigquery.py", line 1917, in run_load
    job = self.insert_job(configuration=configuration, project_id=self.project_id)
  File "/home/airflow/.local/lib/python3.7/site-packages/airflow/providers/google/common/hooks/base_google.py", line 430, in inner_wrapper
    return func(self, *args, **kwargs)
  File "/home/airflow/.local/lib/python3.7/site-packages/airflow/providers/google/cloud/hooks/bigquery.py", line 1639, in insert_job
    job.result()
  File "/home/airflow/.local/lib/python3.7/site-packages/google/cloud/bigquery/job/base.py", line 724, in result
    self._begin(retry=retry, timeout=timeout)
  File "/home/airflow/.local/lib/python3.7/site-packages/google/cloud/bigquery/job/base.py", line 517, in _begin
    timeout=timeout,
  File "/home/airflow/.local/lib/python3.7/site-packages/google/cloud/bigquery/client.py", line 782, in _call_api
    return call()
  File "/home/airflow/.local/lib/python3.7/site-packages/google/api_core/retry.py", line 291, in retry_wrapped_func
    on_error=on_error,
  File "/home/airflow/.local/lib/python3.7/site-packages/google/api_core/retry.py", line 189, in retry_target
    return target()
  File "/home/airflow/.local/lib/python3.7/site-packages/google/cloud/_http.py", line 484, in api_request
    raise exceptions.from_http_response(response)
google.api_core.exceptions.NotFound: 404 POST https://bigquery.googleapis.com/bigquery/v2/projects/dataengineering-bizzy/jobs?prettyPrint=false: Not found: Dataset dataengineering-bizzy:ny_trips_from_dag
[2022-01-27 14:45:24,217] {taskinstance.py:1277} INFO - Marking task as UP_FOR_RETRY. dag_id=data_ingestion_gcs_dag, task_id=gcs_to_bq_task, execution_date=20220127T144516, start_date=20220127T144522, end_date=20220127T144524
[2022-01-27 14:45:24,297] {standard_task_runner.py:92} ERROR - Failed to execute job 10 for task gcs_to_bq_task
Traceback (most recent call last):
  File "/home/airflow/.local/lib/python3.7/site-packages/airflow/task/task_runner/standard_task_runner.py", line 85, in _start_by_fork
    args.func(args, dag=self.dag)
  File "/home/airflow/.local/lib/python3.7/site-packages/airflow/cli/cli_parser.py", line 48, in command
    return func(*args, **kwargs)
  File "/home/airflow/.local/lib/python3.7/site-packages/airflow/utils/cli.py", line 92, in wrapper
    return f(*args, **kwargs)
  File "/home/airflow/.local/lib/python3.7/site-packages/airflow/cli/commands/task_command.py", line 298, in task_run
    _run_task_by_selected_method(args, dag, ti)
  File "/home/airflow/.local/lib/python3.7/site-packages/airflow/cli/commands/task_command.py", line 107, in _run_task_by_selected_method
    _run_raw_task(args, ti)
  File "/home/airflow/.local/lib/python3.7/site-packages/airflow/cli/commands/task_command.py", line 184, in _run_raw_task
    error_file=args.error_file,
  File "/home/airflow/.local/lib/python3.7/site-packages/airflow/utils/session.py", line 70, in wrapper
    return func(*args, session=session, **kwargs)
  File "/home/airflow/.local/lib/python3.7/site-packages/airflow/models/taskinstance.py", line 1329, in _run_raw_task
    self._execute_task_with_callbacks(context)
  File "/home/airflow/.local/lib/python3.7/site-packages/airflow/models/taskinstance.py", line 1455, in _execute_task_with_callbacks
    result = self._execute_task(context, self.task)
  File "/home/airflow/.local/lib/python3.7/site-packages/airflow/models/taskinstance.py", line 1511, in _execute_task
    result = execute_callable(context=context)
  File "/home/airflow/.local/lib/python3.7/site-packages/airflow/providers/google/cloud/transfers/gcs_to_bigquery.py", line 329, in execute
    description=self.description,
  File "/home/airflow/.local/lib/python3.7/site-packages/airflow/providers/google/cloud/hooks/bigquery.py", line 2682, in run_load
    return self.hook.run_load(*args, **kwargs)
  File "/home/airflow/.local/lib/python3.7/site-packages/airflow/providers/google/cloud/hooks/bigquery.py", line 1917, in run_load
    job = self.insert_job(configuration=configuration, project_id=self.project_id)
  File "/home/airflow/.local/lib/python3.7/site-packages/airflow/providers/google/common/hooks/base_google.py", line 430, in inner_wrapper
    return func(self, *args, **kwargs)
  File "/home/airflow/.local/lib/python3.7/site-packages/airflow/providers/google/cloud/hooks/bigquery.py", line 1639, in insert_job
    job.result()
  File "/home/airflow/.local/lib/python3.7/site-packages/google/cloud/bigquery/job/base.py", line 724, in result
    self._begin(retry=retry, timeout=timeout)
  File "/home/airflow/.local/lib/python3.7/site-packages/google/cloud/bigquery/job/base.py", line 517, in _begin
    timeout=timeout,
  File "/home/airflow/.local/lib/python3.7/site-packages/google/cloud/bigquery/client.py", line 782, in _call_api
    return call()
  File "/home/airflow/.local/lib/python3.7/site-packages/google/api_core/retry.py", line 291, in retry_wrapped_func
    on_error=on_error,
  File "/home/airflow/.local/lib/python3.7/site-packages/google/api_core/retry.py", line 189, in retry_target
    return target()
  File "/home/airflow/.local/lib/python3.7/site-packages/google/cloud/_http.py", line 484, in api_request
    raise exceptions.from_http_response(response)
google.api_core.exceptions.NotFound: 404 POST https://bigquery.googleapis.com/bigquery/v2/projects/dataengineering-bizzy/jobs?prettyPrint=false: Not found: Dataset dataengineering-bizzy:ny_trips_from_dag
[2022-01-27 14:45:24,357] {local_task_job.py:154} INFO - Task exited with return code 1
[2022-01-27 14:45:24,474] {local_task_job.py:264} INFO - 0 downstream tasks scheduled from follow-on schedule check
