[2022-02-10 13:52:58,985] {taskinstance.py:1032} INFO - Dependencies all met for <TaskInstance: green_taxi_download_ingest_2_gcs_dag.local_to_gcs_green scheduled__2019-01-02T06:00:00+00:00 [queued]>
[2022-02-10 13:52:59,039] {taskinstance.py:1032} INFO - Dependencies all met for <TaskInstance: green_taxi_download_ingest_2_gcs_dag.local_to_gcs_green scheduled__2019-01-02T06:00:00+00:00 [queued]>
[2022-02-10 13:52:59,041] {taskinstance.py:1238} INFO - 
--------------------------------------------------------------------------------
[2022-02-10 13:52:59,044] {taskinstance.py:1239} INFO - Starting attempt 2 of 2
[2022-02-10 13:52:59,045] {taskinstance.py:1240} INFO - 
--------------------------------------------------------------------------------
[2022-02-10 13:52:59,111] {taskinstance.py:1259} INFO - Executing <Task(PythonOperator): local_to_gcs_green> on 2019-01-02 06:00:00+00:00
[2022-02-10 13:52:59,129] {standard_task_runner.py:52} INFO - Started process 768 to run task
[2022-02-10 13:52:59,145] {standard_task_runner.py:76} INFO - Running: ['***', 'tasks', 'run', 'green_taxi_download_ingest_2_gcs_dag', 'local_to_gcs_green', 'scheduled__2019-01-02T06:00:00+00:00', '--job-id', '546', '--raw', '--subdir', 'DAGS_FOLDER/greentaxi_download_2_gcs.py', '--cfg-path', '/tmp/tmpmogsszfc', '--error-file', '/tmp/tmp52bl5ope']
[2022-02-10 13:52:59,150] {standard_task_runner.py:77} INFO - Job 546: Subtask local_to_gcs_green
[2022-02-10 13:52:59,349] {logging_mixin.py:109} INFO - Running <TaskInstance: green_taxi_download_ingest_2_gcs_dag.local_to_gcs_green scheduled__2019-01-02T06:00:00+00:00 [running]> on host e30cdf5fe267
[2022-02-10 13:52:59,490] {warnings.py:110} WARNING - /home/***/.local/lib/python3.7/site-packages/***/utils/context.py:152: AirflowContextDeprecationWarning: Accessing 'execution_date' from the template is deprecated and will be removed in a future version. Please use 'data_interval_start' or 'logical_date' instead.
  warnings.warn(_create_deprecation_warning(key, self._deprecation_replacements[key]))

[2022-02-10 13:52:59,559] {taskinstance.py:1426} INFO - Exporting the following env vars:
AIRFLOW_CTX_DAG_OWNER=***
AIRFLOW_CTX_DAG_ID=green_taxi_download_ingest_2_gcs_dag
AIRFLOW_CTX_TASK_ID=local_to_gcs_green
AIRFLOW_CTX_EXECUTION_DATE=2019-01-02T06:00:00+00:00
AIRFLOW_CTX_DAG_RUN_ID=scheduled__2019-01-02T06:00:00+00:00
[2022-02-10 13:53:02,580] {_metadata.py:104} WARNING - Compute Engine Metadata server unavailable on attempt 1 of 3. Reason: timed out
[2022-02-10 13:53:02,586] {_metadata.py:104} WARNING - Compute Engine Metadata server unavailable on attempt 2 of 3. Reason: [Errno 111] Connection refused
[2022-02-10 13:53:02,590] {_metadata.py:104} WARNING - Compute Engine Metadata server unavailable on attempt 3 of 3. Reason: [Errno 111] Connection refused
[2022-02-10 13:53:02,592] {_default.py:287} WARNING - Authentication failed using Compute Engine authentication due to unavailable metadata server.
[2022-02-10 13:53:02,595] {taskinstance.py:1700} ERROR - Task failed with exception
Traceback (most recent call last):
  File "/home/airflow/.local/lib/python3.7/site-packages/airflow/models/taskinstance.py", line 1329, in _run_raw_task
    self._execute_task_with_callbacks(context)
  File "/home/airflow/.local/lib/python3.7/site-packages/airflow/models/taskinstance.py", line 1455, in _execute_task_with_callbacks
    result = self._execute_task(context, self.task)
  File "/home/airflow/.local/lib/python3.7/site-packages/airflow/models/taskinstance.py", line 1511, in _execute_task
    result = execute_callable(context=context)
  File "/home/airflow/.local/lib/python3.7/site-packages/airflow/operators/python.py", line 174, in execute
    return_value = self.execute_callable()
  File "/home/airflow/.local/lib/python3.7/site-packages/airflow/operators/python.py", line 185, in execute_callable
    return self.python_callable(*self.op_args, **self.op_kwargs)
  File "/opt/airflow/dags/greentaxi_download_2_gcs.py", line 49, in upload_to_gcs
    client = storage.Client()
  File "/home/airflow/.local/lib/python3.7/site-packages/google/cloud/storage/client.py", line 128, in __init__
    _http=_http,
  File "/home/airflow/.local/lib/python3.7/site-packages/google/cloud/client.py", line 318, in __init__
    _ClientProjectMixin.__init__(self, project=project, credentials=credentials)
  File "/home/airflow/.local/lib/python3.7/site-packages/google/cloud/client.py", line 266, in __init__
    project = self._determine_default(project)
  File "/home/airflow/.local/lib/python3.7/site-packages/google/cloud/client.py", line 285, in _determine_default
    return _determine_default_project(project)
  File "/home/airflow/.local/lib/python3.7/site-packages/google/cloud/_helpers.py", line 186, in _determine_default_project
    _, project = google.auth.default()
  File "/home/airflow/.local/lib/python3.7/site-packages/google/auth/_default.py", line 488, in default
    raise exceptions.DefaultCredentialsError(_HELP_MESSAGE)
google.auth.exceptions.DefaultCredentialsError: Could not automatically determine credentials. Please set GOOGLE_APPLICATION_CREDENTIALS or explicitly create credentials and re-run the application. For more information, please see https://cloud.google.com/docs/authentication/getting-started
[2022-02-10 13:53:02,661] {taskinstance.py:1277} INFO - Marking task as FAILED. dag_id=green_taxi_download_ingest_2_gcs_dag, task_id=local_to_gcs_green, execution_date=20190102T060000, start_date=20220210T135258, end_date=20220210T135302
[2022-02-10 13:53:02,722] {standard_task_runner.py:92} ERROR - Failed to execute job 546 for task local_to_gcs_green
Traceback (most recent call last):
  File "/home/airflow/.local/lib/python3.7/site-packages/airflow/task/task_runner/standard_task_runner.py", line 85, in _start_by_fork
    args.func(args, dag=self.dag)
  File "/home/airflow/.local/lib/python3.7/site-packages/airflow/cli/cli_parser.py", line 48, in command
    return func(*args, **kwargs)
  File "/home/airflow/.local/lib/python3.7/site-packages/airflow/utils/cli.py", line 92, in wrapper
    return f(*args, **kwargs)
  File "/home/airflow/.local/lib/python3.7/site-packages/airflow/cli/commands/task_command.py", line 298, in task_run
    _run_task_by_selected_method(args, dag, ti)
  File "/home/airflow/.local/lib/python3.7/site-packages/airflow/cli/commands/task_command.py", line 107, in _run_task_by_selected_method
    _run_raw_task(args, ti)
  File "/home/airflow/.local/lib/python3.7/site-packages/airflow/cli/commands/task_command.py", line 184, in _run_raw_task
    error_file=args.error_file,
  File "/home/airflow/.local/lib/python3.7/site-packages/airflow/utils/session.py", line 70, in wrapper
    return func(*args, session=session, **kwargs)
  File "/home/airflow/.local/lib/python3.7/site-packages/airflow/models/taskinstance.py", line 1329, in _run_raw_task
    self._execute_task_with_callbacks(context)
  File "/home/airflow/.local/lib/python3.7/site-packages/airflow/models/taskinstance.py", line 1455, in _execute_task_with_callbacks
    result = self._execute_task(context, self.task)
  File "/home/airflow/.local/lib/python3.7/site-packages/airflow/models/taskinstance.py", line 1511, in _execute_task
    result = execute_callable(context=context)
  File "/home/airflow/.local/lib/python3.7/site-packages/airflow/operators/python.py", line 174, in execute
    return_value = self.execute_callable()
  File "/home/airflow/.local/lib/python3.7/site-packages/airflow/operators/python.py", line 185, in execute_callable
    return self.python_callable(*self.op_args, **self.op_kwargs)
  File "/opt/airflow/dags/greentaxi_download_2_gcs.py", line 49, in upload_to_gcs
    client = storage.Client()
  File "/home/airflow/.local/lib/python3.7/site-packages/google/cloud/storage/client.py", line 128, in __init__
    _http=_http,
  File "/home/airflow/.local/lib/python3.7/site-packages/google/cloud/client.py", line 318, in __init__
    _ClientProjectMixin.__init__(self, project=project, credentials=credentials)
  File "/home/airflow/.local/lib/python3.7/site-packages/google/cloud/client.py", line 266, in __init__
    project = self._determine_default(project)
  File "/home/airflow/.local/lib/python3.7/site-packages/google/cloud/client.py", line 285, in _determine_default
    return _determine_default_project(project)
  File "/home/airflow/.local/lib/python3.7/site-packages/google/cloud/_helpers.py", line 186, in _determine_default_project
    _, project = google.auth.default()
  File "/home/airflow/.local/lib/python3.7/site-packages/google/auth/_default.py", line 488, in default
    raise exceptions.DefaultCredentialsError(_HELP_MESSAGE)
google.auth.exceptions.DefaultCredentialsError: Could not automatically determine credentials. Please set GOOGLE_APPLICATION_CREDENTIALS or explicitly create credentials and re-run the application. For more information, please see https://cloud.google.com/docs/authentication/getting-started
[2022-02-10 13:53:02,805] {local_task_job.py:154} INFO - Task exited with return code 1
[2022-02-10 13:53:03,004] {local_task_job.py:264} INFO - 0 downstream tasks scheduled from follow-on schedule check
