[2022-02-15 22:47:29,650] {taskinstance.py:1032} INFO - Dependencies all met for <TaskInstance: green_taxi_download_csv.cleanup_csv scheduled__2019-02-02T06:00:00+00:00 [queued]>
[2022-02-15 22:47:29,802] {taskinstance.py:1032} INFO - Dependencies all met for <TaskInstance: green_taxi_download_csv.cleanup_csv scheduled__2019-02-02T06:00:00+00:00 [queued]>
[2022-02-15 22:47:29,806] {taskinstance.py:1238} INFO - 
--------------------------------------------------------------------------------
[2022-02-15 22:47:29,808] {taskinstance.py:1239} INFO - Starting attempt 1 of 1
[2022-02-15 22:47:29,810] {taskinstance.py:1240} INFO - 
--------------------------------------------------------------------------------
[2022-02-15 22:47:30,016] {taskinstance.py:1259} INFO - Executing <Task(BashOperator): cleanup_csv> on 2019-02-02 06:00:00+00:00
[2022-02-15 22:47:30,066] {standard_task_runner.py:52} INFO - Started process 5253 to run task
[2022-02-15 22:47:30,141] {standard_task_runner.py:76} INFO - Running: ['***', 'tasks', 'run', 'green_taxi_download_csv', 'cleanup_csv', 'scheduled__2019-02-02T06:00:00+00:00', '--job-id', '748', '--raw', '--subdir', 'DAGS_FOLDER/download_upload_greentaxi_csv.py', '--cfg-path', '/tmp/tmpd_9xw2uj', '--error-file', '/tmp/tmp4yy4xm1q']
[2022-02-15 22:47:30,158] {standard_task_runner.py:77} INFO - Job 748: Subtask cleanup_csv
[2022-02-15 22:47:30,980] {logging_mixin.py:109} INFO - Running <TaskInstance: green_taxi_download_csv.cleanup_csv scheduled__2019-02-02T06:00:00+00:00 [running]> on host 29988b24dbed
[2022-02-15 22:47:31,528] {warnings.py:110} WARNING - /home/***/.local/lib/python3.7/site-packages/***/utils/context.py:152: AirflowContextDeprecationWarning: Accessing 'execution_date' from the template is deprecated and will be removed in a future version. Please use 'data_interval_start' or 'logical_date' instead.
  warnings.warn(_create_deprecation_warning(key, self._deprecation_replacements[key]))

[2022-02-15 22:47:31,698] {taskinstance.py:1426} INFO - Exporting the following env vars:
AIRFLOW_CTX_DAG_OWNER=***
AIRFLOW_CTX_DAG_ID=green_taxi_download_csv
AIRFLOW_CTX_TASK_ID=cleanup_csv
AIRFLOW_CTX_EXECUTION_DATE=2019-02-02T06:00:00+00:00
AIRFLOW_CTX_DAG_RUN_ID=scheduled__2019-02-02T06:00:00+00:00
[2022-02-15 22:47:31,711] {subprocess.py:62} INFO - Tmp dir root location: 
 /tmp
[2022-02-15 22:47:31,715] {subprocess.py:74} INFO - Running command: ['bash', '-c', 'rm /opt/***/output_2019-02.csv']
[2022-02-15 22:47:31,795] {subprocess.py:85} INFO - Output:
[2022-02-15 22:47:32,074] {subprocess.py:89} INFO - /bin/rm: cannot remove '/opt/***/output_2019-02.csv': No such file or directory
[2022-02-15 22:47:32,088] {subprocess.py:93} INFO - Command exited with return code 1
[2022-02-15 22:47:32,270] {taskinstance.py:1700} ERROR - Task failed with exception
Traceback (most recent call last):
  File "/home/airflow/.local/lib/python3.7/site-packages/airflow/models/taskinstance.py", line 1329, in _run_raw_task
    self._execute_task_with_callbacks(context)
  File "/home/airflow/.local/lib/python3.7/site-packages/airflow/models/taskinstance.py", line 1455, in _execute_task_with_callbacks
    result = self._execute_task(context, self.task)
  File "/home/airflow/.local/lib/python3.7/site-packages/airflow/models/taskinstance.py", line 1511, in _execute_task
    result = execute_callable(context=context)
  File "/home/airflow/.local/lib/python3.7/site-packages/airflow/operators/bash.py", line 188, in execute
    f'Bash command failed. The command returned a non-zero exit code {result.exit_code}.'
airflow.exceptions.AirflowException: Bash command failed. The command returned a non-zero exit code 1.
[2022-02-15 22:47:32,497] {taskinstance.py:1277} INFO - Marking task as FAILED. dag_id=green_taxi_download_csv, task_id=cleanup_csv, execution_date=20190202T060000, start_date=20220215T224729, end_date=20220215T224732
[2022-02-15 22:47:32,720] {standard_task_runner.py:92} ERROR - Failed to execute job 748 for task cleanup_csv
Traceback (most recent call last):
  File "/home/airflow/.local/lib/python3.7/site-packages/airflow/task/task_runner/standard_task_runner.py", line 85, in _start_by_fork
    args.func(args, dag=self.dag)
  File "/home/airflow/.local/lib/python3.7/site-packages/airflow/cli/cli_parser.py", line 48, in command
    return func(*args, **kwargs)
  File "/home/airflow/.local/lib/python3.7/site-packages/airflow/utils/cli.py", line 92, in wrapper
    return f(*args, **kwargs)
  File "/home/airflow/.local/lib/python3.7/site-packages/airflow/cli/commands/task_command.py", line 298, in task_run
    _run_task_by_selected_method(args, dag, ti)
  File "/home/airflow/.local/lib/python3.7/site-packages/airflow/cli/commands/task_command.py", line 107, in _run_task_by_selected_method
    _run_raw_task(args, ti)
  File "/home/airflow/.local/lib/python3.7/site-packages/airflow/cli/commands/task_command.py", line 184, in _run_raw_task
    error_file=args.error_file,
  File "/home/airflow/.local/lib/python3.7/site-packages/airflow/utils/session.py", line 70, in wrapper
    return func(*args, session=session, **kwargs)
  File "/home/airflow/.local/lib/python3.7/site-packages/airflow/models/taskinstance.py", line 1329, in _run_raw_task
    self._execute_task_with_callbacks(context)
  File "/home/airflow/.local/lib/python3.7/site-packages/airflow/models/taskinstance.py", line 1455, in _execute_task_with_callbacks
    result = self._execute_task(context, self.task)
  File "/home/airflow/.local/lib/python3.7/site-packages/airflow/models/taskinstance.py", line 1511, in _execute_task
    result = execute_callable(context=context)
  File "/home/airflow/.local/lib/python3.7/site-packages/airflow/operators/bash.py", line 188, in execute
    f'Bash command failed. The command returned a non-zero exit code {result.exit_code}.'
airflow.exceptions.AirflowException: Bash command failed. The command returned a non-zero exit code 1.
[2022-02-15 22:47:32,837] {local_task_job.py:154} INFO - Task exited with return code 1
[2022-02-15 22:47:33,101] {local_task_job.py:264} INFO - 0 downstream tasks scheduled from follow-on schedule check
