[2022-02-02 06:16:56,838] {taskinstance.py:1032} INFO - Dependencies all met for <TaskInstance: download_ingest_2_gcs_dag.cleanup_csv scheduled__2019-02-02T06:00:00+00:00 [queued]>
[2022-02-02 06:16:56,893] {taskinstance.py:1032} INFO - Dependencies all met for <TaskInstance: download_ingest_2_gcs_dag.cleanup_csv scheduled__2019-02-02T06:00:00+00:00 [queued]>
[2022-02-02 06:16:56,895] {taskinstance.py:1238} INFO - 
--------------------------------------------------------------------------------
[2022-02-02 06:16:56,897] {taskinstance.py:1239} INFO - Starting attempt 1 of 1
[2022-02-02 06:16:56,899] {taskinstance.py:1240} INFO - 
--------------------------------------------------------------------------------
[2022-02-02 06:16:56,958] {taskinstance.py:1259} INFO - Executing <Task(BashOperator): cleanup_csv> on 2019-02-02 06:00:00+00:00
[2022-02-02 06:16:56,972] {standard_task_runner.py:52} INFO - Started process 8970 to run task
[2022-02-02 06:16:56,998] {standard_task_runner.py:76} INFO - Running: ['***', 'tasks', 'run', 'download_ingest_2_gcs_dag', 'cleanup_csv', 'scheduled__2019-02-02T06:00:00+00:00', '--job-id', '288', '--raw', '--subdir', 'DAGS_FOLDER/download_ingest_2_gsc_assgnment.py', '--cfg-path', '/tmp/tmp07lge4j5', '--error-file', '/tmp/tmpp59oe744']
[2022-02-02 06:16:57,003] {standard_task_runner.py:77} INFO - Job 288: Subtask cleanup_csv
[2022-02-02 06:16:57,199] {logging_mixin.py:109} INFO - Running <TaskInstance: download_ingest_2_gcs_dag.cleanup_csv scheduled__2019-02-02T06:00:00+00:00 [running]> on host 3082aca3aebc
[2022-02-02 06:16:57,421] {taskinstance.py:1426} INFO - Exporting the following env vars:
AIRFLOW_CTX_DAG_OWNER=***
AIRFLOW_CTX_DAG_ID=download_ingest_2_gcs_dag
AIRFLOW_CTX_TASK_ID=cleanup_csv
AIRFLOW_CTX_EXECUTION_DATE=2019-02-02T06:00:00+00:00
AIRFLOW_CTX_DAG_RUN_ID=scheduled__2019-02-02T06:00:00+00:00
[2022-02-02 06:16:57,431] {subprocess.py:62} INFO - Tmp dir root location: 
 /tmp
[2022-02-02 06:16:57,435] {subprocess.py:74} INFO - Running command: ['bash', '-c', 'rm /opt/***\\*.csv']
[2022-02-02 06:16:57,482] {subprocess.py:85} INFO - Output:
[2022-02-02 06:16:57,651] {subprocess.py:89} INFO - /bin/rm: cannot remove '/opt/****.csv': No such file or directory
[2022-02-02 06:16:57,658] {subprocess.py:93} INFO - Command exited with return code 1
[2022-02-02 06:16:57,745] {taskinstance.py:1700} ERROR - Task failed with exception
Traceback (most recent call last):
  File "/home/airflow/.local/lib/python3.7/site-packages/airflow/models/taskinstance.py", line 1329, in _run_raw_task
    self._execute_task_with_callbacks(context)
  File "/home/airflow/.local/lib/python3.7/site-packages/airflow/models/taskinstance.py", line 1455, in _execute_task_with_callbacks
    result = self._execute_task(context, self.task)
  File "/home/airflow/.local/lib/python3.7/site-packages/airflow/models/taskinstance.py", line 1511, in _execute_task
    result = execute_callable(context=context)
  File "/home/airflow/.local/lib/python3.7/site-packages/airflow/operators/bash.py", line 188, in execute
    f'Bash command failed. The command returned a non-zero exit code {result.exit_code}.'
airflow.exceptions.AirflowException: Bash command failed. The command returned a non-zero exit code 1.
[2022-02-02 06:16:57,810] {taskinstance.py:1277} INFO - Marking task as FAILED. dag_id=download_ingest_2_gcs_dag, task_id=cleanup_csv, execution_date=20190202T060000, start_date=20220202T061656, end_date=20220202T061657
[2022-02-02 06:16:57,883] {standard_task_runner.py:92} ERROR - Failed to execute job 288 for task cleanup_csv
Traceback (most recent call last):
  File "/home/airflow/.local/lib/python3.7/site-packages/airflow/task/task_runner/standard_task_runner.py", line 85, in _start_by_fork
    args.func(args, dag=self.dag)
  File "/home/airflow/.local/lib/python3.7/site-packages/airflow/cli/cli_parser.py", line 48, in command
    return func(*args, **kwargs)
  File "/home/airflow/.local/lib/python3.7/site-packages/airflow/utils/cli.py", line 92, in wrapper
    return f(*args, **kwargs)
  File "/home/airflow/.local/lib/python3.7/site-packages/airflow/cli/commands/task_command.py", line 298, in task_run
    _run_task_by_selected_method(args, dag, ti)
  File "/home/airflow/.local/lib/python3.7/site-packages/airflow/cli/commands/task_command.py", line 107, in _run_task_by_selected_method
    _run_raw_task(args, ti)
  File "/home/airflow/.local/lib/python3.7/site-packages/airflow/cli/commands/task_command.py", line 184, in _run_raw_task
    error_file=args.error_file,
  File "/home/airflow/.local/lib/python3.7/site-packages/airflow/utils/session.py", line 70, in wrapper
    return func(*args, session=session, **kwargs)
  File "/home/airflow/.local/lib/python3.7/site-packages/airflow/models/taskinstance.py", line 1329, in _run_raw_task
    self._execute_task_with_callbacks(context)
  File "/home/airflow/.local/lib/python3.7/site-packages/airflow/models/taskinstance.py", line 1455, in _execute_task_with_callbacks
    result = self._execute_task(context, self.task)
  File "/home/airflow/.local/lib/python3.7/site-packages/airflow/models/taskinstance.py", line 1511, in _execute_task
    result = execute_callable(context=context)
  File "/home/airflow/.local/lib/python3.7/site-packages/airflow/operators/bash.py", line 188, in execute
    f'Bash command failed. The command returned a non-zero exit code {result.exit_code}.'
airflow.exceptions.AirflowException: Bash command failed. The command returned a non-zero exit code 1.
[2022-02-02 06:16:57,939] {local_task_job.py:154} INFO - Task exited with return code 1
[2022-02-02 06:16:58,047] {local_task_job.py:264} INFO - 0 downstream tasks scheduled from follow-on schedule check
