[2022-01-29 00:00:27,115] {taskinstance.py:1032} INFO - Dependencies all met for <TaskInstance: new_data_ingestion_gcs_dag.download_dataset_task scheduled__2022-01-28T00:00:00+00:00 [queued]>
[2022-01-29 00:00:27,193] {taskinstance.py:1032} INFO - Dependencies all met for <TaskInstance: new_data_ingestion_gcs_dag.download_dataset_task scheduled__2022-01-28T00:00:00+00:00 [queued]>
[2022-01-29 00:00:27,195] {taskinstance.py:1238} INFO - 
--------------------------------------------------------------------------------
[2022-01-29 00:00:27,197] {taskinstance.py:1239} INFO - Starting attempt 1 of 2
[2022-01-29 00:00:27,198] {taskinstance.py:1240} INFO - 
--------------------------------------------------------------------------------
[2022-01-29 00:00:27,282] {taskinstance.py:1259} INFO - Executing <Task(BashOperator): download_dataset_task> on 2022-01-28 00:00:00+00:00
[2022-01-29 00:00:27,311] {standard_task_runner.py:52} INFO - Started process 21545 to run task
[2022-01-29 00:00:27,327] {standard_task_runner.py:76} INFO - Running: ['***', 'tasks', 'run', 'new_data_ingestion_gcs_dag', 'download_dataset_task', 'scheduled__2022-01-28T00:00:00+00:00', '--job-id', '31', '--raw', '--subdir', 'DAGS_FOLDER/ingest_parquet_data_gcs.py', '--cfg-path', '/tmp/tmpjlts0adc', '--error-file', '/tmp/tmpow_mnqvd']
[2022-01-29 00:00:27,338] {standard_task_runner.py:77} INFO - Job 31: Subtask download_dataset_task
[2022-01-29 00:00:27,639] {logging_mixin.py:109} INFO - Running <TaskInstance: new_data_ingestion_gcs_dag.download_dataset_task scheduled__2022-01-28T00:00:00+00:00 [running]> on host eb911b0bf7cc
[2022-01-29 00:00:27,932] {taskinstance.py:1426} INFO - Exporting the following env vars:
AIRFLOW_CTX_DAG_OWNER=***
AIRFLOW_CTX_DAG_ID=new_data_ingestion_gcs_dag
AIRFLOW_CTX_TASK_ID=download_dataset_task
AIRFLOW_CTX_EXECUTION_DATE=2022-01-28T00:00:00+00:00
AIRFLOW_CTX_DAG_RUN_ID=scheduled__2022-01-28T00:00:00+00:00
[2022-01-29 00:00:27,938] {subprocess.py:62} INFO - Tmp dir root location: 
 /tmp
[2022-01-29 00:00:27,944] {subprocess.py:74} INFO - Running command: ['bash', '-c', 'curl -sS https://s3.amazonaws.com/nyc-tlc/trip+data/yellow_tripdata_2021-01.csv > /opt/***/yellow_tripdata_2021-01.csv']
[2022-01-29 00:00:27,976] {subprocess.py:85} INFO - Output:
[2022-01-29 00:00:33,517] {subprocess.py:89} INFO - curl: (18) transfer closed with 48238302 bytes remaining to read
[2022-01-29 00:00:33,568] {subprocess.py:93} INFO - Command exited with return code 18
[2022-01-29 00:00:33,765] {taskinstance.py:1700} ERROR - Task failed with exception
Traceback (most recent call last):
  File "/home/airflow/.local/lib/python3.7/site-packages/airflow/models/taskinstance.py", line 1329, in _run_raw_task
    self._execute_task_with_callbacks(context)
  File "/home/airflow/.local/lib/python3.7/site-packages/airflow/models/taskinstance.py", line 1455, in _execute_task_with_callbacks
    result = self._execute_task(context, self.task)
  File "/home/airflow/.local/lib/python3.7/site-packages/airflow/models/taskinstance.py", line 1511, in _execute_task
    result = execute_callable(context=context)
  File "/home/airflow/.local/lib/python3.7/site-packages/airflow/operators/bash.py", line 188, in execute
    f'Bash command failed. The command returned a non-zero exit code {result.exit_code}.'
airflow.exceptions.AirflowException: Bash command failed. The command returned a non-zero exit code 18.
[2022-01-29 00:00:33,832] {taskinstance.py:1277} INFO - Marking task as UP_FOR_RETRY. dag_id=new_data_ingestion_gcs_dag, task_id=download_dataset_task, execution_date=20220128T000000, start_date=20220129T000027, end_date=20220129T000033
[2022-01-29 00:00:33,935] {standard_task_runner.py:92} ERROR - Failed to execute job 31 for task download_dataset_task
Traceback (most recent call last):
  File "/home/airflow/.local/lib/python3.7/site-packages/airflow/task/task_runner/standard_task_runner.py", line 85, in _start_by_fork
    args.func(args, dag=self.dag)
  File "/home/airflow/.local/lib/python3.7/site-packages/airflow/cli/cli_parser.py", line 48, in command
    return func(*args, **kwargs)
  File "/home/airflow/.local/lib/python3.7/site-packages/airflow/utils/cli.py", line 92, in wrapper
    return f(*args, **kwargs)
  File "/home/airflow/.local/lib/python3.7/site-packages/airflow/cli/commands/task_command.py", line 298, in task_run
    _run_task_by_selected_method(args, dag, ti)
  File "/home/airflow/.local/lib/python3.7/site-packages/airflow/cli/commands/task_command.py", line 107, in _run_task_by_selected_method
    _run_raw_task(args, ti)
  File "/home/airflow/.local/lib/python3.7/site-packages/airflow/cli/commands/task_command.py", line 184, in _run_raw_task
    error_file=args.error_file,
  File "/home/airflow/.local/lib/python3.7/site-packages/airflow/utils/session.py", line 70, in wrapper
    return func(*args, session=session, **kwargs)
  File "/home/airflow/.local/lib/python3.7/site-packages/airflow/models/taskinstance.py", line 1329, in _run_raw_task
    self._execute_task_with_callbacks(context)
  File "/home/airflow/.local/lib/python3.7/site-packages/airflow/models/taskinstance.py", line 1455, in _execute_task_with_callbacks
    result = self._execute_task(context, self.task)
  File "/home/airflow/.local/lib/python3.7/site-packages/airflow/models/taskinstance.py", line 1511, in _execute_task
    result = execute_callable(context=context)
  File "/home/airflow/.local/lib/python3.7/site-packages/airflow/operators/bash.py", line 188, in execute
    f'Bash command failed. The command returned a non-zero exit code {result.exit_code}.'
airflow.exceptions.AirflowException: Bash command failed. The command returned a non-zero exit code 18.
[2022-01-29 00:00:33,978] {local_task_job.py:154} INFO - Task exited with return code 1
[2022-01-29 00:00:34,200] {local_task_job.py:264} INFO - 0 downstream tasks scheduled from follow-on schedule check
