[2022-02-10 15:01:36,408] {taskinstance.py:1032} INFO - Dependencies all met for <TaskInstance: zone_ingest_2_gcs_dag.upload_to_gcs_job_zone scheduled__2022-01-02T06:00:00+00:00 [queued]>
[2022-02-10 15:01:36,468] {taskinstance.py:1032} INFO - Dependencies all met for <TaskInstance: zone_ingest_2_gcs_dag.upload_to_gcs_job_zone scheduled__2022-01-02T06:00:00+00:00 [queued]>
[2022-02-10 15:01:36,471] {taskinstance.py:1238} INFO - 
--------------------------------------------------------------------------------
[2022-02-10 15:01:36,472] {taskinstance.py:1239} INFO - Starting attempt 13 of 13
[2022-02-10 15:01:36,474] {taskinstance.py:1240} INFO - 
--------------------------------------------------------------------------------
[2022-02-10 15:01:36,533] {taskinstance.py:1259} INFO - Executing <Task(PythonOperator): upload_to_gcs_job_zone> on 2022-01-02 06:00:00+00:00
[2022-02-10 15:01:36,551] {standard_task_runner.py:52} INFO - Started process 805 to run task
[2022-02-10 15:01:36,595] {standard_task_runner.py:76} INFO - Running: ['***', 'tasks', 'run', 'zone_ingest_2_gcs_dag', 'upload_to_gcs_job_zone', 'scheduled__2022-01-02T06:00:00+00:00', '--job-id', '562', '--raw', '--subdir', 'DAGS_FOLDER/zone_download_ingest_gcs.py', '--cfg-path', '/tmp/tmplys3ku1o', '--error-file', '/tmp/tmpeno5bwa7']
[2022-02-10 15:01:36,599] {standard_task_runner.py:77} INFO - Job 562: Subtask upload_to_gcs_job_zone
[2022-02-10 15:01:36,767] {logging_mixin.py:109} INFO - Running <TaskInstance: zone_ingest_2_gcs_dag.upload_to_gcs_job_zone scheduled__2022-01-02T06:00:00+00:00 [running]> on host 263e19c9abf1
[2022-02-10 15:01:36,943] {taskinstance.py:1426} INFO - Exporting the following env vars:
AIRFLOW_CTX_DAG_OWNER=***
AIRFLOW_CTX_DAG_ID=zone_ingest_2_gcs_dag
AIRFLOW_CTX_TASK_ID=upload_to_gcs_job_zone
AIRFLOW_CTX_EXECUTION_DATE=2022-01-02T06:00:00+00:00
AIRFLOW_CTX_DAG_RUN_ID=scheduled__2022-01-02T06:00:00+00:00
[2022-02-10 15:01:36,949] {taskinstance.py:1700} ERROR - Task failed with exception
Traceback (most recent call last):
  File "/home/airflow/.local/lib/python3.7/site-packages/airflow/models/taskinstance.py", line 1329, in _run_raw_task
    self._execute_task_with_callbacks(context)
  File "/home/airflow/.local/lib/python3.7/site-packages/airflow/models/taskinstance.py", line 1455, in _execute_task_with_callbacks
    result = self._execute_task(context, self.task)
  File "/home/airflow/.local/lib/python3.7/site-packages/airflow/models/taskinstance.py", line 1511, in _execute_task
    result = execute_callable(context=context)
  File "/home/airflow/.local/lib/python3.7/site-packages/airflow/operators/python.py", line 174, in execute
    return_value = self.execute_callable()
  File "/home/airflow/.local/lib/python3.7/site-packages/airflow/operators/python.py", line 185, in execute_callable
    return self.python_callable(*self.op_args, **self.op_kwargs)
  File "/opt/airflow/dags/zone_download_ingest_gcs.py", line 48, in upload_to_gcs
    client = storage.Client()
  File "/home/airflow/.local/lib/python3.7/site-packages/google/cloud/storage/client.py", line 128, in __init__
    _http=_http,
  File "/home/airflow/.local/lib/python3.7/site-packages/google/cloud/client.py", line 318, in __init__
    _ClientProjectMixin.__init__(self, project=project, credentials=credentials)
  File "/home/airflow/.local/lib/python3.7/site-packages/google/cloud/client.py", line 266, in __init__
    project = self._determine_default(project)
  File "/home/airflow/.local/lib/python3.7/site-packages/google/cloud/client.py", line 285, in _determine_default
    return _determine_default_project(project)
  File "/home/airflow/.local/lib/python3.7/site-packages/google/cloud/_helpers.py", line 186, in _determine_default_project
    _, project = google.auth.default()
  File "/home/airflow/.local/lib/python3.7/site-packages/google/auth/_default.py", line 459, in default
    credentials, project_id = checker()
  File "/home/airflow/.local/lib/python3.7/site-packages/google/auth/_default.py", line 222, in _get_explicit_environ_credentials
    os.environ[environment_vars.CREDENTIALS]
  File "/home/airflow/.local/lib/python3.7/site-packages/google/auth/_default.py", line 108, in load_credentials_from_file
    "File {} was not found.".format(filename)
google.auth.exceptions.DefaultCredentialsError: File /Users/gabidoye/Downloads/dataengineering-bizzy-770f13466383.json was not found.
[2022-02-10 15:01:37,001] {taskinstance.py:1277} INFO - Marking task as FAILED. dag_id=zone_ingest_2_gcs_dag, task_id=upload_to_gcs_job_zone, execution_date=20220102T060000, start_date=20220210T150136, end_date=20220210T150136
[2022-02-10 15:01:37,058] {standard_task_runner.py:92} ERROR - Failed to execute job 562 for task upload_to_gcs_job_zone
Traceback (most recent call last):
  File "/home/airflow/.local/lib/python3.7/site-packages/airflow/task/task_runner/standard_task_runner.py", line 85, in _start_by_fork
    args.func(args, dag=self.dag)
  File "/home/airflow/.local/lib/python3.7/site-packages/airflow/cli/cli_parser.py", line 48, in command
    return func(*args, **kwargs)
  File "/home/airflow/.local/lib/python3.7/site-packages/airflow/utils/cli.py", line 92, in wrapper
    return f(*args, **kwargs)
  File "/home/airflow/.local/lib/python3.7/site-packages/airflow/cli/commands/task_command.py", line 298, in task_run
    _run_task_by_selected_method(args, dag, ti)
  File "/home/airflow/.local/lib/python3.7/site-packages/airflow/cli/commands/task_command.py", line 107, in _run_task_by_selected_method
    _run_raw_task(args, ti)
  File "/home/airflow/.local/lib/python3.7/site-packages/airflow/cli/commands/task_command.py", line 184, in _run_raw_task
    error_file=args.error_file,
  File "/home/airflow/.local/lib/python3.7/site-packages/airflow/utils/session.py", line 70, in wrapper
    return func(*args, session=session, **kwargs)
  File "/home/airflow/.local/lib/python3.7/site-packages/airflow/models/taskinstance.py", line 1329, in _run_raw_task
    self._execute_task_with_callbacks(context)
  File "/home/airflow/.local/lib/python3.7/site-packages/airflow/models/taskinstance.py", line 1455, in _execute_task_with_callbacks
    result = self._execute_task(context, self.task)
  File "/home/airflow/.local/lib/python3.7/site-packages/airflow/models/taskinstance.py", line 1511, in _execute_task
    result = execute_callable(context=context)
  File "/home/airflow/.local/lib/python3.7/site-packages/airflow/operators/python.py", line 174, in execute
    return_value = self.execute_callable()
  File "/home/airflow/.local/lib/python3.7/site-packages/airflow/operators/python.py", line 185, in execute_callable
    return self.python_callable(*self.op_args, **self.op_kwargs)
  File "/opt/airflow/dags/zone_download_ingest_gcs.py", line 48, in upload_to_gcs
    client = storage.Client()
  File "/home/airflow/.local/lib/python3.7/site-packages/google/cloud/storage/client.py", line 128, in __init__
    _http=_http,
  File "/home/airflow/.local/lib/python3.7/site-packages/google/cloud/client.py", line 318, in __init__
    _ClientProjectMixin.__init__(self, project=project, credentials=credentials)
  File "/home/airflow/.local/lib/python3.7/site-packages/google/cloud/client.py", line 266, in __init__
    project = self._determine_default(project)
  File "/home/airflow/.local/lib/python3.7/site-packages/google/cloud/client.py", line 285, in _determine_default
    return _determine_default_project(project)
  File "/home/airflow/.local/lib/python3.7/site-packages/google/cloud/_helpers.py", line 186, in _determine_default_project
    _, project = google.auth.default()
  File "/home/airflow/.local/lib/python3.7/site-packages/google/auth/_default.py", line 459, in default
    credentials, project_id = checker()
  File "/home/airflow/.local/lib/python3.7/site-packages/google/auth/_default.py", line 222, in _get_explicit_environ_credentials
    os.environ[environment_vars.CREDENTIALS]
  File "/home/airflow/.local/lib/python3.7/site-packages/google/auth/_default.py", line 108, in load_credentials_from_file
    "File {} was not found.".format(filename)
google.auth.exceptions.DefaultCredentialsError: File /Users/gabidoye/Downloads/dataengineering-bizzy-770f13466383.json was not found.
[2022-02-10 15:01:37,098] {local_task_job.py:154} INFO - Task exited with return code 1
[2022-02-10 15:01:37,271] {local_task_job.py:264} INFO - 0 downstream tasks scheduled from follow-on schedule check
