[2022-02-10 15:45:26,136] {taskinstance.py:1032} INFO - Dependencies all met for <TaskInstance: zone_ingest_2_gcs_dag.upload_to_gcs_job_zone scheduled__2022-01-02T06:00:00+00:00 [queued]>
[2022-02-10 15:45:26,175] {taskinstance.py:1032} INFO - Dependencies all met for <TaskInstance: zone_ingest_2_gcs_dag.upload_to_gcs_job_zone scheduled__2022-01-02T06:00:00+00:00 [queued]>
[2022-02-10 15:45:26,176] {taskinstance.py:1238} INFO - 
--------------------------------------------------------------------------------
[2022-02-10 15:45:26,178] {taskinstance.py:1239} INFO - Starting attempt 15 of 15
[2022-02-10 15:45:26,179] {taskinstance.py:1240} INFO - 
--------------------------------------------------------------------------------
[2022-02-10 15:45:26,223] {taskinstance.py:1259} INFO - Executing <Task(PythonOperator): upload_to_gcs_job_zone> on 2022-01-02 06:00:00+00:00
[2022-02-10 15:45:26,233] {standard_task_runner.py:52} INFO - Started process 583 to run task
[2022-02-10 15:45:26,242] {standard_task_runner.py:76} INFO - Running: ['***', 'tasks', 'run', 'zone_ingest_2_gcs_dag', 'upload_to_gcs_job_zone', 'scheduled__2022-01-02T06:00:00+00:00', '--job-id', '568', '--raw', '--subdir', 'DAGS_FOLDER/zone_download_ingest_gcs.py', '--cfg-path', '/tmp/tmp5oh93rb0', '--error-file', '/tmp/tmpkley1e75']
[2022-02-10 15:45:26,245] {standard_task_runner.py:77} INFO - Job 568: Subtask upload_to_gcs_job_zone
[2022-02-10 15:45:26,402] {logging_mixin.py:109} INFO - Running <TaskInstance: zone_ingest_2_gcs_dag.upload_to_gcs_job_zone scheduled__2022-01-02T06:00:00+00:00 [running]> on host 8b3b8f04337e
[2022-02-10 15:45:26,561] {taskinstance.py:1426} INFO - Exporting the following env vars:
AIRFLOW_CTX_DAG_OWNER=***
AIRFLOW_CTX_DAG_ID=zone_ingest_2_gcs_dag
AIRFLOW_CTX_TASK_ID=upload_to_gcs_job_zone
AIRFLOW_CTX_EXECUTION_DATE=2022-01-02T06:00:00+00:00
AIRFLOW_CTX_DAG_RUN_ID=scheduled__2022-01-02T06:00:00+00:00
[2022-02-10 15:45:29,580] {_metadata.py:104} WARNING - Compute Engine Metadata server unavailable on attempt 1 of 3. Reason: timed out
[2022-02-10 15:45:32,586] {_metadata.py:104} WARNING - Compute Engine Metadata server unavailable on attempt 2 of 3. Reason: timed out
[2022-02-10 15:45:32,590] {_metadata.py:104} WARNING - Compute Engine Metadata server unavailable on attempt 3 of 3. Reason: [Errno 111] Connection refused
[2022-02-10 15:45:32,592] {_default.py:287} WARNING - Authentication failed using Compute Engine authentication due to unavailable metadata server.
[2022-02-10 15:45:32,594] {taskinstance.py:1700} ERROR - Task failed with exception
Traceback (most recent call last):
  File "/home/airflow/.local/lib/python3.7/site-packages/airflow/models/taskinstance.py", line 1329, in _run_raw_task
    self._execute_task_with_callbacks(context)
  File "/home/airflow/.local/lib/python3.7/site-packages/airflow/models/taskinstance.py", line 1455, in _execute_task_with_callbacks
    result = self._execute_task(context, self.task)
  File "/home/airflow/.local/lib/python3.7/site-packages/airflow/models/taskinstance.py", line 1511, in _execute_task
    result = execute_callable(context=context)
  File "/home/airflow/.local/lib/python3.7/site-packages/airflow/operators/python.py", line 174, in execute
    return_value = self.execute_callable()
  File "/home/airflow/.local/lib/python3.7/site-packages/airflow/operators/python.py", line 185, in execute_callable
    return self.python_callable(*self.op_args, **self.op_kwargs)
  File "/opt/airflow/dags/zone_download_ingest_gcs.py", line 48, in upload_to_gcs
    client = storage.Client()
  File "/home/airflow/.local/lib/python3.7/site-packages/google/cloud/storage/client.py", line 128, in __init__
    _http=_http,
  File "/home/airflow/.local/lib/python3.7/site-packages/google/cloud/client.py", line 318, in __init__
    _ClientProjectMixin.__init__(self, project=project, credentials=credentials)
  File "/home/airflow/.local/lib/python3.7/site-packages/google/cloud/client.py", line 266, in __init__
    project = self._determine_default(project)
  File "/home/airflow/.local/lib/python3.7/site-packages/google/cloud/client.py", line 285, in _determine_default
    return _determine_default_project(project)
  File "/home/airflow/.local/lib/python3.7/site-packages/google/cloud/_helpers.py", line 186, in _determine_default_project
    _, project = google.auth.default()
  File "/home/airflow/.local/lib/python3.7/site-packages/google/auth/_default.py", line 488, in default
    raise exceptions.DefaultCredentialsError(_HELP_MESSAGE)
google.auth.exceptions.DefaultCredentialsError: Could not automatically determine credentials. Please set GOOGLE_APPLICATION_CREDENTIALS or explicitly create credentials and re-run the application. For more information, please see https://cloud.google.com/docs/authentication/getting-started
[2022-02-10 15:45:32,651] {taskinstance.py:1277} INFO - Marking task as FAILED. dag_id=zone_ingest_2_gcs_dag, task_id=upload_to_gcs_job_zone, execution_date=20220102T060000, start_date=20220210T154526, end_date=20220210T154532
[2022-02-10 15:45:32,710] {standard_task_runner.py:92} ERROR - Failed to execute job 568 for task upload_to_gcs_job_zone
Traceback (most recent call last):
  File "/home/airflow/.local/lib/python3.7/site-packages/airflow/task/task_runner/standard_task_runner.py", line 85, in _start_by_fork
    args.func(args, dag=self.dag)
  File "/home/airflow/.local/lib/python3.7/site-packages/airflow/cli/cli_parser.py", line 48, in command
    return func(*args, **kwargs)
  File "/home/airflow/.local/lib/python3.7/site-packages/airflow/utils/cli.py", line 92, in wrapper
    return f(*args, **kwargs)
  File "/home/airflow/.local/lib/python3.7/site-packages/airflow/cli/commands/task_command.py", line 298, in task_run
    _run_task_by_selected_method(args, dag, ti)
  File "/home/airflow/.local/lib/python3.7/site-packages/airflow/cli/commands/task_command.py", line 107, in _run_task_by_selected_method
    _run_raw_task(args, ti)
  File "/home/airflow/.local/lib/python3.7/site-packages/airflow/cli/commands/task_command.py", line 184, in _run_raw_task
    error_file=args.error_file,
  File "/home/airflow/.local/lib/python3.7/site-packages/airflow/utils/session.py", line 70, in wrapper
    return func(*args, session=session, **kwargs)
  File "/home/airflow/.local/lib/python3.7/site-packages/airflow/models/taskinstance.py", line 1329, in _run_raw_task
    self._execute_task_with_callbacks(context)
  File "/home/airflow/.local/lib/python3.7/site-packages/airflow/models/taskinstance.py", line 1455, in _execute_task_with_callbacks
    result = self._execute_task(context, self.task)
  File "/home/airflow/.local/lib/python3.7/site-packages/airflow/models/taskinstance.py", line 1511, in _execute_task
    result = execute_callable(context=context)
  File "/home/airflow/.local/lib/python3.7/site-packages/airflow/operators/python.py", line 174, in execute
    return_value = self.execute_callable()
  File "/home/airflow/.local/lib/python3.7/site-packages/airflow/operators/python.py", line 185, in execute_callable
    return self.python_callable(*self.op_args, **self.op_kwargs)
  File "/opt/airflow/dags/zone_download_ingest_gcs.py", line 48, in upload_to_gcs
    client = storage.Client()
  File "/home/airflow/.local/lib/python3.7/site-packages/google/cloud/storage/client.py", line 128, in __init__
    _http=_http,
  File "/home/airflow/.local/lib/python3.7/site-packages/google/cloud/client.py", line 318, in __init__
    _ClientProjectMixin.__init__(self, project=project, credentials=credentials)
  File "/home/airflow/.local/lib/python3.7/site-packages/google/cloud/client.py", line 266, in __init__
    project = self._determine_default(project)
  File "/home/airflow/.local/lib/python3.7/site-packages/google/cloud/client.py", line 285, in _determine_default
    return _determine_default_project(project)
  File "/home/airflow/.local/lib/python3.7/site-packages/google/cloud/_helpers.py", line 186, in _determine_default_project
    _, project = google.auth.default()
  File "/home/airflow/.local/lib/python3.7/site-packages/google/auth/_default.py", line 488, in default
    raise exceptions.DefaultCredentialsError(_HELP_MESSAGE)
google.auth.exceptions.DefaultCredentialsError: Could not automatically determine credentials. Please set GOOGLE_APPLICATION_CREDENTIALS or explicitly create credentials and re-run the application. For more information, please see https://cloud.google.com/docs/authentication/getting-started
[2022-02-10 15:45:32,755] {local_task_job.py:154} INFO - Task exited with return code 1
[2022-02-10 15:45:32,903] {local_task_job.py:264} INFO - 0 downstream tasks scheduled from follow-on schedule check
